Workbook
Name NAV_CG: 'PAINEL - CG'!#REF!
Name NAV_CG: 'PAINEL - HPLC'!#REF!
Name NAV_CG: 'PAINEL - BANCADA'!#REF!
Name NAV_CTRL: 'PAINEL - CG'!#REF!
Name NAV_CTRL: 'PAINEL - HPLC'!#REF!
Name NAV_CTRL: 'PAINEL - BANCADA'!#REF!
Name NAV_EXCIP: 'PAINEL - CG'!#REF!
Name NAV_EXCIP: 'PAINEL - HPLC'!#REF!
Name NAV_EXCIP: 'PAINEL - BANCADA'!#REF!
Name NAV_FAST: 'PAINEL - CG'!#REF!
Name NAV_FAST: 'PAINEL - HPLC'!#REF!
Name NAV_FAST: 'PAINEL - BANCADA'!#REF!
Name NAV_FAST_EQUIP: 'PAINEL - BANCADA'!#REF!
Name NAV_HOJE: 'PAINEL - CG'!$M$4
Name NAV_HOJE: 'PAINEL - HPLC'!$M$4
Name NAV_HOJE: 'PAINEL - BANCADA'!$N$4
Name NAV_HPLC: 'PAINEL - CG'!#REF!
Name NAV_HPLC: 'PAINEL - HPLC'!#REF!
Name NAV_HPLC: 'PAINEL - BANCADA'!#REF!
Name NAV_IFA: 'PAINEL - CG'!#REF!
Name NAV_IFA: 'PAINEL - HPLC'!#REF!
Name NAV_IFA: 'PAINEL - BANCADA'!#REF!
Name NAV_TOPO: 'PAINEL - CG'!$C$4
Name NAV_TOPO: 'PAINEL - HPLC'!$C$4
Name NAV_TOPO: 'PAINEL - BANCADA'!$C$4
Name NAV_UV: 'PAINEL - CG'!#REF!
Name NAV_UV: 'PAINEL - HPLC'!#REF!
Name NAV_UV: 'PAINEL - BANCADA'!#REF!

Sheet QUARENTENA
A1: *Cole abaixo os dados atualizados do BI de quarentena MP | J1: Link Power BI
A2: Centro | B2: Codigo_MP | C2: Depósito | D2: Lote | F2: QtdeNecessariaPCP | G2: Dt_Recebimento_Amostra | H2: Dt_Fim_Analise | I2: Status | J2: Tipo_Demanda | K2: Estorno | L2: Lote_Duplicado | M2: Dt_Liberacao
A3: 2010 | B3: 210308 | C3: 3000 | D3: 10002026 | E3: DIOXIDO SILICIO | F3: 360 | G3: 46247 | H3: 46253 | I3: DU APROVADO | K3: FALSE | M3: 46253
A4: 5001 | B4: 465346 | C4: 3000 | D4: 100112023 | E4: PREDNISOLONA 2 | F4: 200000 | G4: 45897 | H4: 45906 | I4: DU APROVADO | K4: FALSE | L4: TRANSFERÊNCIA | M4: 45908
A5: 2010 | B5: 460298 | C5: 3000 | D5: 10012026 | E5: GOMA GUAR HIGUM 55-I | F5: 200 | G5: 46246 | H5: 46252 | I5: DU APROVADO | K5: FALSE | M5: 46252
A6: 5001 | B6: 465346 | C6: 3000 | D6: 100122023 | E6: PREDNISOLONA 2 | F6: 250000 | G6: 45896 | H6: 45910 | I6: DU APROVADO | K6: FALSE | L6: TRANSFERÊNCIA | M6: 45910
A7: 2010 | B7: 454445 | C7: 3000 | D7: 10022026 | E7: SORBATO POTASSIO | F7: 125 | G7: 46246 | H7: 46252 | I7: DU APROVADO | K7: FALSE | M7: 46252
A8: 5001 | B8: 410385 | C8: 3000 | D8: 100222026 | E8: TIBOLONA MICRONIZADA NEO | F8: 6 | I8: AG. AMOSTRA | K8: FALSE
A9: 2010 | B9: 212225 | C9: 3000 | D9: 10032026 | E9: BENZOATO SODIO | F9: 200 | G9: 46246 | H9: 46252 | I9: DU APROVADO | K9: FALSE | M9: 46252
A10: 2010 | B10: 457673 | C10: 3000 | D10: 10072026 | E10: BISGLICINATO FERRO 20% | F10: 360 | G10: 46247 | H10: 46248 | I10: DU APROVADO | K10: FALSE | M10: 46248
A11: 2010 | B11: 210206 | C11: 3000 | D11: 10082026 | E11: CICLAMATO SODIO | F11: 1 | G11: 46247 | H11: 46247 | I11: DU APROVADO | K11: FALSE | M11: 46247
A12: 2010 | B12: 210206 | C12: 3000 | D12: 10092026 | E12: CICLAMATO SODIO | F12: 5 | G12: 46247 | H12: 46247 | I12: DU APROVADO | K12: FALSE | M12: 46247
A13: 5001 | B13: 463212 | C13: 3000 | D13: 100952026 | E13: HYDRAFENCE | F13: 3 | G13: 46189 | H13: 46191 | I13: DU APROVADO | K13: FALSE | M13: 46191
A14: 5001 | B14: 463212 | C14: 3000 | D14: 100962026 | E14: HYDRAFENCE | F14: 45 | G14: 46189 | H14: 46191 | I14: DU APROVADO | K14: FALSE | M14: 46191
A15: 5001 | B15: 438103 | C15: 3000 | D15: 101022026 | E15: E OXIDO DE FE VERMELHO AQR0401 MTCD | F15: 5 | G15: 46162 | H15: 46167 | I15: DU APROVADO | K15: FALSE | M15: 46167
A16: 5001 | B16: 461957 | C16: 3000 | D16: 101112026 | E16: DIMETICONA | F16: 126 | G16: 46216 | H16: 46231 | I16: DU APROVADO | K16: FALSE | M16: 46232
A17: 5001 | B17: 452975 | C17: 3000 | D17: 101122026 | E17: E SEPIPLUS 400 MTCD | F17: 30 | G17: 46162 | H17: 46164 | I17: DU APROVADO | K17: FALSE | M17: 46164
A18: 5001 | B18: 452975 | C18: 3000 | D18: 101132026 | E18: E SEPIPLUS 400 MTCD | F18: 30 | G18: 46162 | H18: 46164 | I18: DU APROVADO | K18: FALSE | M18: 46164
A19: 5001 | B19: 443705 | C19: 3000 | D19: 101152026 | E19: CLORETO SODIO | F19: 50 | G19: 46199 | H19: 46209 | I19: DU APROVADO | K19: FALSE | M19: 46209
A20: 5001 | B20: 410072 | C20: 3000 | D20: 101222026 | E20: BASE POLIETILENO PETROLATO NEO | F20: 640 | I20: AG. AMOSTRA | K20: FALSE
A21: 2010 | B21: 211904 | C21: 3000 | D21: 10152026 | E21: SORBITOL 70 TANQUE | F21: 32 | G21: 46248 | H21: 46248 | I21: DU APROVADO | K21: FALSE | M21: 46248
A22: 5001 | B22: 410548 | C22: 3000 | D22: 101522025 | E22: DOMPERIDONA NEO | F22: 60 | G22: 45789 | H22: 45903 | I22: DU APROVADO | K22: FALSE | M22: 45903
A23: 5001 | B23: 410548 | C23: 3000 | D23: 101532025 | E23: DOMPERIDONA NEO | F23: 60 | G23: 45789 | H23: 45903 | I23: DU APROVADO | K23: FALSE | M23: 45903
A24: 5001 | B24: 410548 | C24: 3000 | D24: 101542025 | E24: DOMPERIDONA NEO | F24: 62 | G24: 45789 | H24: 45903 | I24: DU APROVADO | K24: FALSE | M24: 45903
A25: 2017 | B25: 461298 | C25: 3010 | D25: 10162026 | E25: AQUARIUS PRIME BKT517004 BLUE | F25: 50 | I25: AG. AMOSTRA | K25: FALSE
A26: 2017 | B26: 461298 | C26: 3010 | D26: 10172026 | E26: AQUARIUS PRIME BKT517004 BLUE | F26: 50 | I26: AG. AMOSTRA | K26: FALSE
A27: 5001 | B27: 457350 | C27: 3000 | D27: 101792026 | E27: LEVOMENTOL | F27: 25 | G27: 46213 | H27: 46220 | I27: DU APROVADO | K27: FALSE | M27: 46220
A28: 5001 | B28: 457350 | C28: 3000 | D28: 101802026 | E28: LEVOMENTOL | F28: 25 | G28: 46212 | H28: 46220 | I28: DU APROVADO | K28: FALSE | M28: 46220
A29: 2017 | B29: 471654 | C29: 3010 | D29: 10192026 | E29: OXIDO ZINCO AL | F29: 100 | G29: 46214 | H29: 46220 | I29: DU APROVADO | K29: FALSE | M29: 46220
A30: 5001 | B30: 410000 | C30: 3000 | D30: 101952026 | E30: ESSENCIA DE BAUNILHA HIDROSS REF 501 NEO | F30: 22 | G30: 46182 | H30: 46184 | I30: DU APROVADO | K30: FALSE | M30: 46185
A31: 5001 | B31: 409970 | C31: 3000 | D31: 101972026 | E31: BENZOATO DE SODIO NEO | F31: 750 | G31: 46161 | H31: 46174 | I31: DU APROVADO | K31: FALSE | M31: 46174
A32: 5001 | B32: 410018 | C32: 3000 | D32: 102082026 | E32: POLIETILENOGLICOL 400 CARBOWAX 400 NEO | F32: 2 | I32: AG. AMOSTRA | K32: FALSE
A33: 5001 | B33: 460361 | C33: 3000 | D33: 102112026 | E33: CETIOL ULTIMATE | F33: 310 | G33: 46172 | H33: 46175 | I33: DU APROVADO | K33: FALSE | M33: 46175
A34: 5001 | B34: 473869 | C34: 3000 | D34: 102392023 | E34: ACIDO ASCORBICO QF | G34: 45878 | H34: 45902 | I34: DU APROVADO | K34: FALSE | L34: REVALIDAÇÃO | M34: 45902
A35: 5001 | B35: 478553 | C35: 3000 | D35: 102412026 | E35: PARACETAMOL QF3 | F35: 100 | I35: AG. AMOSTRA | K35: FALSE
A36: 5001 | B36: 478553 | C36: 3000 | D36: 102422026 | E36: PARACETAMOL QF3 | F36: 100 | I36: AG. AMOSTRA | K36: FALSE
A37: 5001 | B37: 478553 | C37: 3000 | D37: 102432026 | E37: PARACETAMOL QF3 | F37: 100 | I37: AG. AMOSTRA | K37: FALSE
A38: 5001 | B38: 478553 | C38: 3000 | D38: 102442026 | E38: PARACETAMOL QF3 | F38: 100 | I38: AG. AMOSTRA | K38: FALSE
A39: 5001 | B39: 422388 | C39: 3000 | D39: 102452023 | E39: DIPIRONA MONOIDRATADA | F39: 3125 | I39: AG. AMOSTRA | K39: TRUE
A40: 5001 | B40: 422388 | C40: 3000 | D40: 102462023 | E40: DIPIRONA MONOIDRATADA | F40: 3100 | I40: AG. AMOSTRA | K40: TRUE
...

Sheet DEMANDA
B1: ⚠️ IMPORTANTE: NÃO EXCLUA, MOVA OU ALTERE AS COLUNAS DESTA PLANILHA. QUALQUER MODIFICAÇÃO PODERÁ COMPROMETER O FUNCIONAMENTO DAS FÓRMULAS E AUTOMAÇÕES. | U1: *Campos da equipe de consumíveis
A2: COMANDO | B2: CENTRO (Centro PARA) | C2: CODIGO (Código PARA) | D2: DESCRIÇÃO | E2: LOTE | F2: QUANTIDADE | G2: DATA DE NECESSIDADE DE LIBERAÇÃO PCP | H2: DEMANDA | I2: chave | J2: id | K2: DATA VERIFICAÇÃO CQ/ SOLICITAÇÃO PCP | L2: DATA RECEBIMENTO E-MAIL PCP | M2: D+8 | N2: data previsão PCP - no aplicativo | O2: Status - Planiha de quarentena (NOTA: abastecer Quarentena) | P2: Obs. Programação | Q2: data de DU | R2: Particularidades | S2: Data Programada | T2: Turno Programado | U2: Avaliação Padrão | V2: Avaliação Reagente | W2: Obesrvações
B3: 2017 | C3: 470361 | D3: D-PANTOTENATO DE CALCIO AL | E3: 5382026 | H3: PCP | I3: =Tabela3[[#This Row],[CENTRO (Centro PARA)]]&Tabela3[[#This Row],[CODIGO (Código PARA)]]&Tabela3[[#This Row],[LOTE]]&Tabela3[[#This Row],[DESCRIÇÃO]]&Tabela3[[#This Row],[id]] -> 20174703615382026D-PANTOTENATO DE CALCIO AL1484 | J3: 1484 | K3: 46203 | L3: 46196 | M3: =K3+8 -> 46211 | N3: =IF(WEEKDAY(K3,2)=4,K3+11,IF(WEEKDAY(K3,2)=5,K3+11,K3+10)) -> 46213 | O3: =_xlfn.XLOOKUP(Tabela3[[#This Row],[LOTE]],QUARENTENA!D:D,QUARENTENA!I:I,"") -> AG. AMOSTRA | P3: MATERIAL EM TERCEIRO | Q3: =IF(_xlfn.XLOOKUP(E3,QUARENTENA!D:D,QUARENTENA!M:M,"")="","",_xlfn.XLOOKUP(E3,QUARENTENA!D:D,QUARENTENA!M:M,"")) | R3: =_xlfn.XLOOKUP(C3,'PARTICULARIDADES AUXILIAR '!A:A,'PARTICULARIDADES AUXILIAR '!C:C,"") -> Check doc | S3: {=_xlfn.XLOOKUP(Tabela3[[#This Row],[LOTE]],VALUE(Painel_Bancada[Lote]),Painel_Bancada[Data Programada],"")} | T3: =_xlfn.XLOOKUP(Tabela3[[#This Row],[LOTE]],'PAINEL - GERAL'!F:F,'PAINEL - GERAL'!C:C,"")
B4: 2017 | C4: 461291 | D4: ALCOOL 96 GL 92,8 INPM | E4: 11472026 | H4: OPORTUNIDADE | I4: =Tabela3[[#This Row],[CENTRO (Centro PARA)]]&Tabela3[[#This Row],[CODIGO (Código PARA)]]&Tabela3[[#This Row],[LOTE]]&Tabela3[[#This Row],[DESCRIÇÃO]]&Tabela3[[#This Row],[id]] -> 201746129111472026ALCOOL 96 GL 92,8 INPM1522 | J4: 1522 | K4: 46204 | L4: 46197 | M4: =K4+8 -> 46212 | N4: =IF(WEEKDAY(K4,2)=4,K4+11,IF(WEEKDAY(K4,2)=5,K4+11,K4+10)) -> 46214 | O4: =_xlfn.XLOOKUP(Tabela3[[#This Row],[LOTE]],QUARENTENA!D:D,QUARENTENA!I:I,"") -> DU APROVADO | Q4: =IF(_xlfn.XLOOKUP(E4,QUARENTENA!D:D,QUARENTENA!M:M,"")="","",_xlfn.XLOOKUP(E4,QUARENTENA!D:D,QUARENTENA!M:M,"")) -> 46276 | R4: =_xlfn.XLOOKUP(C4,'PARTICULARIDADES AUXILIAR '!A:A,'PARTICULARIDADES AUXILIAR '!C:C,"") -> Inflamável/ Check doc | S4: {=_xlfn.XLOOKUP(Tabela3[[#This Row],[LOTE]],VALUE(Painel_Bancada[Lote]),Painel_Bancada[Data Programada],"")} | T4: =_xlfn.XLOOKUP(Tabela3[[#This Row],[LOTE]],'PAINEL - GERAL'!F:F,'PAINEL - GERAL'!C:C,"")
B5: 2017 | C5: 461287 | D5: L CISTEINA HCl | E5: 1882026 | H5: PCP | I5: =Tabela3[[#This Row],[CENTRO (Centro PARA)]]&Tabela3[[#This Row],[CODIGO (Código PARA)]]&Tabela3[[#This Row],[LOTE]]&Tabela3[[#This Row],[DESCRIÇÃO]]&Tabela3[[#This Row],[id]] -> 20174612871882026L CISTEINA HCl1518 | J5: 1518 | K5: 46204 | L5: 46197 | M5: =K5+8 -> 46212 | N5: =IF(WEEKDAY(K5,2)=4,K5+11,IF(WEEKDAY(K5,2)=5,K5+11,K5+10)) -> 46214 | O5: AVARIA | Q5: =IF(_xlfn.XLOOKUP(E5,QUARENTENA!D:D,QUARENTENA!M:M,"")="","",_xlfn.XLOOKUP(E5,QUARENTENA!D:D,QUARENTENA!M:M,"")) | R5: =_xlfn.XLOOKUP(C5,'PARTICULARIDADES AUXILIAR '!A:A,'PARTICULARIDADES AUXILIAR '!C:C,"") -> Check doc | S5: {=_xlfn.XLOOKUP(Tabela3[[#This Row],[LOTE]],VALUE(Painel_Bancada[Lote]),Painel_Bancada[Data Programada],"")} | T5: =_xlfn.XLOOKUP(Tabela3[[#This Row],[LOTE]],'PAINEL - GERAL'!F:F,'PAINEL - GERAL'!C:C,"")
B6: 2017 | C6: 474703 | D6: EXTRATO SUCO DE MARACUJA | E6: 11062026 | H6: PCP | I6: =Tabela3[[#This Row],[CENTRO (Centro PARA)]]&Tabela3[[#This Row],[CODIGO (Código PARA)]]&Tabela3[[#This Row],[LOTE]]&Tabela3[[#This Row],[DESCRIÇÃO]]&Tabela3[[#This Row],[id]] -> 201747470311062026EXTRATO SUCO DE MARACUJA1531 | J6: 1531 | K6: 46205 | L6: 46198 | M6: =K6+8 -> 46213 | N6: =IF(WEEKDAY(K6,2)=4,K6+11,IF(WEEKDAY(K6,2)=5,K6+11,K6+10)) -> 46216 | O6: =_xlfn.XLOOKUP(Tabela3[[#This Row],[LOTE]],QUARENTENA!D:D,QUARENTENA!I:I,"") -> DU APROVADO | Q6: =IF(_xlfn.XLOOKUP(E6,QUARENTENA!D:D,QUARENTENA!M:M,"")="","",_xlfn.XLOOKUP(E6,QUARENTENA!D:D,QUARENTENA!M:M,"")) -> 46273 | R6: =_xlfn.XLOOKUP(C6,'PARTICULARIDADES AUXILIAR '!A:A,'PARTICULARIDADES AUXILIAR '!C:C,"") -> Check doc | S6: {=_xlfn.XLOOKUP(Tabela3[[#This Row],[LOTE]],VALUE(Painel_Bancada[Lote]),Painel_Bancada[Data Programada],"")} | T6: =_xlfn.XLOOKUP(Tabela3[[#This Row],[LOTE]],'PAINEL - GERAL'!F:F,'PAINEL - GERAL'!C:C,"")
B7: 5001 | C7: 410033 | D7: CELULOSE MICROCRISTALINA MC101 NEO | E7: 263502025 | H7: OPORTUNIDADE | I7: =Tabela3[[#This Row],[CENTRO (Centro PARA)]]&Tabela3[[#This Row],[CODIGO (Código PARA)]]&Tabela3[[#This Row],[LOTE]]&Tabela3[[#This Row],[DESCRIÇÃO]]&Tabela3[[#This Row],[id]] -> 5001410033263502025CELULOSE MICROCRISTALINA MC101 NEO1695 | J7: 1695 | K7: 46211 | L7: 46204 | M7: =K7+8 -> 46219 | N7: =IF(WEEKDAY(K7,2)=4,K7+11,IF(WEEKDAY(K7,2)=5,K7+11,K7+10)) -> 46221 | O7: =_xlfn.XLOOKUP(Tabela3[[#This Row],[LOTE]],QUARENTENA!D:D,QUARENTENA!I:I,"") -> AG. AMOSTRA | P7: CANCELADO PELA AMOSTRAGEM | Q7: =IF(_xlfn.XLOOKUP(E7,QUARENTENA!D:D,QUARENTENA!M:M,"")="","",_xlfn.XLOOKUP(E7,QUARENTENA!D:D,QUARENTENA!M:M,"")) | R7: =_xlfn.XLOOKUP(C7,'PARTICULARIDADES AUXILIAR '!A:A,'PARTICULARIDADES AUXILIAR '!C:C,"") | S7: {=_xlfn.XLOOKUP(Tabela3[[#This Row],[LOTE]],VALUE(Painel_Bancada[Lote]),Painel_Bancada[Data Programada],"")} | T7: =_xlfn.XLOOKUP(Tabela3[[#This Row],[LOTE]],'PAINEL - GERAL'!F:F,'PAINEL - GERAL'!C:C,"")
B8: ID 3083 | C8: 410527 | D8: MESALAZINA NEO | E8: 137082026 | H8: PCP | I8: =Tabela3[[#This Row],[CENTRO (Centro PARA)]]&Tabela3[[#This Row],[CODIGO (Código PARA)]]&Tabela3[[#This Row],[LOTE]]&Tabela3[[#This Row],[DESCRIÇÃO]]&Tabela3[[#This Row],[id]] -> ID 3083 410527137082026MESALAZINA NEO1688 | J8: 1688 | K8: 46211 | L8: 46204 | M8: =K8+8 -> 46219 | N8: =IF(WEEKDAY(K8,2)=4,K8+11,IF(WEEKDAY(K8,2)=5,K8+11,K8+10)) -> 46221 | O8: =_xlfn.XLOOKUP(Tabela3[[#This Row],[LOTE]],QUARENTENA!D:D,QUARENTENA!I:I,"") -> INVESTIGAÇÃO P&D | Q8: =IF(_xlfn.XLOOKUP(E8,QUARENTENA!D:D,QUARENTENA!M:M,"")="","",_xlfn.XLOOKUP(E8,QUARENTENA!D:D,QUARENTENA!M:M,"")) | R8: =_xlfn.XLOOKUP(C8,'PARTICULARIDADES AUXILIAR '!A:A,'PARTICULARIDADES AUXILIAR '!C:C,"") | S8: {=_xlfn.XLOOKUP(Tabela3[[#This Row],[LOTE]],VALUE(Painel_Bancada[Lote]),Painel_Bancada[Data Programada],"")} -> 46211 | T8: =_xlfn.XLOOKUP(Tabela3[[#This Row],[LOTE]],'PAINEL - GERAL'!F:F,'PAINEL - GERAL'!C:C,"")
A9: P | B9: 5001 | C9: 425491 | D9: A VALERATO DE BETA USP MICRON MTC | E9: 221972025 | H9: OPORTUNIDADE | I9: =Tabela3[[#This Row],[CENTRO (Centro PARA)]]&Tabela3[[#This Row],[CODIGO (Código PARA)]]&Tabela3[[#This Row],[LOTE]]&Tabela3[[#This Row],[DESCRIÇÃO]]&Tabela3[[#This Row],[id]] -> 5001425491221972025A VALERATO DE BETA USP MICRON MTC1788 | J9: 1788 | K9: 46213 | L9: 46206 | M9: =K9+8 -> 46221 | N9: =IF(WEEKDAY(K9,2)=4,K9+11,IF(WEEKDAY(K9,2)=5,K9+11,K9+10)) -> 46224 | O9: =_xlfn.XLOOKUP(Tabela3[[#This Row],[LOTE]],QUARENTENA!D:D,QUARENTENA!I:I,"") -> AG. PROGRAMAÇÃO | Q9: =IF(_xlfn.XLOOKUP(E9,QUARENTENA!D:D,QUARENTENA!M:M,"")="","",_xlfn.XLOOKUP(E9,QUARENTENA!D:D,QUARENTENA!M:M,"")) | R9: =_xlfn.XLOOKUP(C9,'PARTICULARIDADES AUXILIAR '!A:A,'PARTICULARIDADES AUXILIAR '!C:C,"") | S9: {=_xlfn.XLOOKUP(Tabela3[[#This Row],[LOTE]],VALUE(Painel_Bancada[Lote]),Painel_Bancada[Data Programada],"")} | T9: =_xlfn.XLOOKUP(Tabela3[[#This Row],[LOTE]],'PAINEL - GERAL'!F:F,'PAINEL - GERAL'!C:C,"")
B10: 5001 | C10: 464484 | D10: MSS 500 W | E10: 138132026 | H10: PCP | I10: =Tabela3[[#This Row],[CENTRO (Centro PARA)]]&Tabela3[[#This Row],[CODIGO (Código PARA)]]&Tabela3[[#This Row],[LOTE]]&Tabela3[[#This Row],[DESCRIÇÃO]]&Tabela3[[#This Row],[id]] -> 5001464484138132026MSS 500 W1814 | J10: 1814 | K10: 46216 | L10: 46209 | M10: =K10+8 -> 46224 | N10: =IF(WEEKDAY(K10,2)=4,K10+11,IF(WEEKDAY(K10,2)=5,K10+11,K10+10)) -> 46226 | O10: =_xlfn.XLOOKUP(Tabela3[[#This Row],[LOTE]],QUARENTENA!D:D,QUARENTENA!I:I,"") -> DU APROVADO | P10: MATERIAL EM TERCEIRO | Q10: =IF(_xlfn.XLOOKUP(E10,QUARENTENA!D:D,QUARENTENA!M:M,"")="","",_xlfn.XLOOKUP(E10,QUARENTENA!D:D,QUARENTENA!M:M,"")) -> 46283 | R10: =_xlfn.XLOOKUP(C10,'PARTICULARIDADES AUXILIAR '!A:A,'PARTICULARIDADES AUXILIAR '!C:C,"") -> Check doc | S10: {=_xlfn.XLOOKUP(Tabela3[[#This Row],[LOTE]],VALUE(Painel_Bancada[Lote]),Painel_Bancada[Data Programada],"")} | T10: =_xlfn.XLOOKUP(Tabela3[[#This Row],[LOTE]],'PAINEL - GERAL'!F:F,'PAINEL - GERAL'!C:C,"")
B11: 5001 | C11: 463406 | D11: CASSIA FISTULA EXTRATO SECO 0,03-0,06% | E11: 135972026 | H11: PCP | I11: =Tabela3[[#This Row],[CENTRO (Centro PARA)]]&Tabela3[[#This Row],[CODIGO (Código PARA)]]&Tabela3[[#This Row],[LOTE]]&Tabela3[[#This Row],[DESCRIÇÃO]]&Tabela3[[#This Row],[id]] -> 5001463406135972026CASSIA FISTULA EXTRATO SECO 0,03-0,06%1865 | J11: 1865 | K11: 46217 | L11: 46210 | M11: =K11+8 -> 46225 | N11: =IF(WEEKDAY(K11,2)=4,K11+11,IF(WEEKDAY(K11,2)=5,K11+11,K11+10)) -> 46227 | O11: =_xlfn.XLOOKUP(Tabela3[[#This Row],[LOTE]],QUARENTENA!D:D,QUARENTENA!I:I,"") -> DU REPROVADO | P11: analise de terceiro | Q11: =IF(_xlfn.XLOOKUP(E11,QUARENTENA!D:D,QUARENTENA!M:M,"")="","",_xlfn.XLOOKUP(E11,QUARENTENA!D:D,QUARENTENA!M:M,"")) -> 46282 | R11: =_xlfn.XLOOKUP(C11,'PARTICULARIDADES AUXILIAR '!A:A,'PARTICULARIDADES AUXILIAR '!C:C,"") -> Pesticidas/ Aflatoxinas - EM TERCEIRO | S11: {=_xlfn.XLOOKUP(Tabela3[[#This Row],[LOTE]],VALUE(Painel_Bancada[Lote]),Painel_Bancada[Data Programada],"")} -> 46240 | T11: =_xlfn.XLOOKUP(Tabela3[[#This Row],[LOTE]],'PAINEL - GERAL'!F:F,'PAINEL - GERAL'!C:C,"")
B12: 5001 | C12: 422364 | D12: CITRATO COLINA | E12: 78632026 | H12: OPORTUNIDADE | I12: =Tabela3[[#This Row],[CENTRO (Centro PARA)]]&Tabela3[[#This Row],[CODIGO (Código PARA)]]&Tabela3[[#This Row],[LOTE]]&Tabela3[[#This Row],[DESCRIÇÃO]]&Tabela3[[#This Row],[id]] -> 500142236478632026CITRATO COLINA1872 | J12: 1872 | K12: 46217 | L12: 46210 | M12: =K12+8 -> 46225 | N12: =IF(WEEKDAY(K12,2)=4,K12+11,IF(WEEKDAY(K12,2)=5,K12+11,K12+10)) -> 46227 | O12: =_xlfn.XLOOKUP(Tabela3[[#This Row],[LOTE]],QUARENTENA!D:D,QUARENTENA!I:I,"") -> DU APROVADO | P12: MATERIAL EM TERCEIRO | Q12: =IF(_xlfn.XLOOKUP(E12,QUARENTENA!D:D,QUARENTENA!M:M,"")="","",_xlfn.XLOOKUP(E12,QUARENTENA!D:D,QUARENTENA!M:M,"")) -> 46280 | R12: =_xlfn.XLOOKUP(C12,'PARTICULARIDADES AUXILIAR '!A:A,'PARTICULARIDADES AUXILIAR '!C:C,"") -> PF - repouso 24 horas | S12: {=_xlfn.XLOOKUP(Tabela3[[#This Row],[LOTE]],VALUE(Painel_Bancada[Lote]),Painel_Bancada[Data Programada],"")} -> 46275 | T12: =_xlfn.XLOOKUP(Tabela3[[#This Row],[LOTE]],'PAINEL - GERAL'!F:F,'PAINEL - GERAL'!C:C,"")
B13: 5001 | C13: 422364 | D13: CITRATO COLINA | E13: 78642026 | H13: OPORTUNIDADE | I13: =Tabela3[[#This Row],[CENTRO (Centro PARA)]]&Tabela3[[#This Row],[CODIGO (Código PARA)]]&Tabela3[[#This Row],[LOTE]]&Tabela3[[#This Row],[DESCRIÇÃO]]&Tabela3[[#This Row],[id]] -> 500142236478642026CITRATO COLINA1873 | J13: 1873 | K13: 46217 | L13: 46210 | M13: =K13+8 -> 46225 | N13: =IF(WEEKDAY(K13,2)=4,K13+11,IF(WEEKDAY(K13,2)=5,K13+11,K13+10)) -> 46227 | O13: =_xlfn.XLOOKUP(Tabela3[[#This Row],[LOTE]],QUARENTENA!D:D,QUARENTENA!I:I,"") -> DU APROVADO | P13: MATERIAL EM TERCEIRO | Q13: =IF(_xlfn.XLOOKUP(E13,QUARENTENA!D:D,QUARENTENA!M:M,"")="","",_xlfn.XLOOKUP(E13,QUARENTENA!D:D,QUARENTENA!M:M,"")) -> 46280 | R13: =_xlfn.XLOOKUP(C13,'PARTICULARIDADES AUXILIAR '!A:A,'PARTICULARIDADES AUXILIAR '!C:C,"") -> PF - repouso 24 horas | S13: {=_xlfn.XLOOKUP(Tabela3[[#This Row],[LOTE]],VALUE(Painel_Bancada[Lote]),Painel_Bancada[Data Programada],"")} -> 46275 | T13: =_xlfn.XLOOKUP(Tabela3[[#This Row],[LOTE]],'PAINEL - GERAL'!F:F,'PAINEL - GERAL'!C:C,"")
B14: 5001 | C14: 422364 | D14: CITRATO COLINA | E14: 78652026 | H14: OPORTUNIDADE | I14: =Tabela3[[#This Row],[CENTRO (Centro PARA)]]&Tabela3[[#This Row],[CODIGO (Código PARA)]]&Tabela3[[#This Row],[LOTE]]&Tabela3[[#This Row],[DESCRIÇÃO]]&Tabela3[[#This Row],[id]] -> 500142236478652026CITRATO COLINA1874 | J14: 1874 | K14: 46217 | L14: 46210 | M14: =K14+8 -> 46225 | N14: =IF(WEEKDAY(K14,2)=4,K14+11,IF(WEEKDAY(K14,2)=5,K14+11,K14+10)) -> 46227 | O14: =_xlfn.XLOOKUP(Tabela3[[#This Row],[LOTE]],QUARENTENA!D:D,QUARENTENA!I:I,"") -> DU APROVADO | P14: MATERIAL EM TERCEIRO | Q14: =IF(_xlfn.XLOOKUP(E14,QUARENTENA!D:D,QUARENTENA!M:M,"")="","",_xlfn.XLOOKUP(E14,QUARENTENA!D:D,QUARENTENA!M:M,"")) -> 46280 | R14: =_xlfn.XLOOKUP(C14,'PARTICULARIDADES AUXILIAR '!A:A,'PARTICULARIDADES AUXILIAR '!C:C,"") -> PF - repouso 24 horas | S14: {=_xlfn.XLOOKUP(Tabela3[[#This Row],[LOTE]],VALUE(Painel_Bancada[Lote]),Painel_Bancada[Data Programada],"")} -> 46275 | T14: =_xlfn.XLOOKUP(Tabela3[[#This Row],[LOTE]],'PAINEL - GERAL'!F:F,'PAINEL - GERAL'!C:C,"")
B15: 5001 | C15: 422364 | D15: CITRATO COLINA | E15: 78662026 | H15: OPORTUNIDADE | I15: =Tabela3[[#This Row],[CENTRO (Centro PARA)]]&Tabela3[[#This Row],[CODIGO (Código PARA)]]&Tabela3[[#This Row],[LOTE]]&Tabela3[[#This Row],[DESCRIÇÃO]]&Tabela3[[#This Row],[id]] -> 500142236478662026CITRATO COLINA1875 | J15: 1875 | K15: 46217 | L15: 46210 | M15: =K15+8 -> 46225 | N15: =IF(WEEKDAY(K15,2)=4,K15+11,IF(WEEKDAY(K15,2)=5,K15+11,K15+10)) -> 46227 | O15: =_xlfn.XLOOKUP(Tabela3[[#This Row],[LOTE]],QUARENTENA!D:D,QUARENTENA!I:I,"") -> DU APROVADO | P15: MATERIAL EM TERCEIRO | Q15: =IF(_xlfn.XLOOKUP(E15,QUARENTENA!D:D,QUARENTENA!M:M,"")="","",_xlfn.XLOOKUP(E15,QUARENTENA!D:D,QUARENTENA!M:M,"")) -> 46280 | R15: =_xlfn.XLOOKUP(C15,'PARTICULARIDADES AUXILIAR '!A:A,'PARTICULARIDADES AUXILIAR '!C:C,"") -> PF - repouso 24 horas | S15: {=_xlfn.XLOOKUP(Tabela3[[#This Row],[LOTE]],VALUE(Painel_Bancada[Lote]),Painel_Bancada[Data Programada],"")} -> 46275 | T15: =_xlfn.XLOOKUP(Tabela3[[#This Row],[LOTE]],'PAINEL - GERAL'!F:F,'PAINEL - GERAL'!C:C,"")
B16: 5001 | C16: 438102 | D16: E OXIDO DE FE AMARELO AQ R0402 MTCD | E16: 138232026 | H16: PCP | I16: =Tabela3[[#This Row],[CENTRO (Centro PARA)]]&Tabela3[[#This Row],[CODIGO (Código PARA)]]&Tabela3[[#This Row],[LOTE]]&Tabela3[[#This Row],[DESCRIÇÃO]]&Tabela3[[#This Row],[id]] -> 5001438102138232026E OXIDO DE FE AMARELO AQ R0402 MTCD1863 | J16: 1863 | K16: 46217 | L16: 46210 | M16: =K16+8 -> 46225 | N16: =IF(WEEKDAY(K16,2)=4,K16+11,IF(WEEKDAY(K16,2)=5,K16+11,K16+10)) -> 46227 | O16: =_xlfn.XLOOKUP(Tabela3[[#This Row],[LOTE]],QUARENTENA!D:D,QUARENTENA!I:I,"") -> DU APROVADO | P16: MATERIAL EM TERCEIRO | Q16: =IF(_xlfn.XLOOKUP(E16,QUARENTENA!D:D,QUARENTENA!M:M,"")="","",_xlfn.XLOOKUP(E16,QUARENTENA!D:D,QUARENTENA!M:M,"")) -> 46282 | R16: =_xlfn.XLOOKUP(C16,'PARTICULARIDADES AUXILIAR '!A:A,'PARTICULARIDADES AUXILIAR '!C:C,"") -> Check doc | S16: {=_xlfn.XLOOKUP(Tabela3[[#This Row],[LOTE]],VALUE(Painel_Bancada[Lote]),Painel_Bancada[Data Programada],"")} | T16: =_xlfn.XLOOKUP(Tabela3[[#This Row],[LOTE]],'PAINEL - GERAL'!F:F,'PAINEL - GERAL'!C:C,"")
B17: 5001 | C17: 410371 | D17: DIAZEPAM B1 NEO | E17: 127522026 | H17: PCP | I17: =Tabela3[[#This Row],[CENTRO (Centro PARA)]]&Tabela3[[#This Row],[CODIGO (Código PARA)]]&Tabela3[[#This Row],[LOTE]]&Tabela3[[#This Row],[DESCRIÇÃO]]&Tabela3[[#This Row],[id]] -> 5001410371127522026DIAZEPAM B1 NEO | K17: 46220 | L17: 46213 | M17: =K17+8 -> 46228 | N17: =IF(WEEKDAY(K17,2)=4,K17+11,IF(WEEKDAY(K17,2)=5,K17+11,K17+10)) -> 46231 | O17: =_xlfn.XLOOKUP(Tabela3[[#This Row],[LOTE]],QUARENTENA!D:D,QUARENTENA!I:I,"") -> INVESTIGAÇÃO P&D | Q17: =IF(_xlfn.XLOOKUP(E17,QUARENTENA!D:D,QUARENTENA!M:M,"")="","",_xlfn.XLOOKUP(E17,QUARENTENA!D:D,QUARENTENA!M:M,"")) | R17: =_xlfn.XLOOKUP(C17,'PARTICULARIDADES AUXILIAR '!A:A,'PARTICULARIDADES AUXILIAR '!C:C,"") -> Portaria 344 | S17: {=_xlfn.XLOOKUP(Tabela3[[#This Row],[LOTE]],VALUE(Painel_Bancada[Lote]),Painel_Bancada[Data Programada],"")} -> 46224 | T17: =_xlfn.XLOOKUP(Tabela3[[#This Row],[LOTE]],'PAINEL - GERAL'!F:F,'PAINEL - GERAL'!C:C,"")
B18: 5001 | C18: 438134 | D18: E ADIPATO DE DIBUTILA MTCD | E18: 147492026 | H18: PCP | I18: 46223 | K18: 46223 | L18: 46216 | M18: =K18+8 -> 46231 | N18: =IF(WEEKDAY(K18,2)=4,K18+11,IF(WEEKDAY(K18,2)=5,K18+11,K18+10)) -> 46233 | O18: =_xlfn.XLOOKUP(Tabela3[[#This Row],[LOTE]],QUARENTENA!D:D,QUARENTENA!I:I,"") -> DU APROVADO | P18: MATERIAL EM TERCEIRO | Q18: =IF(_xlfn.XLOOKUP(E18,QUARENTENA!D:D,QUARENTENA!M:M,"")="","",_xlfn.XLOOKUP(E18,QUARENTENA!D:D,QUARENTENA!M:M,"")) -> 46282 | R18: =_xlfn.XLOOKUP(C18,'PARTICULARIDADES AUXILIAR '!A:A,'PARTICULARIDADES AUXILIAR '!C:C,"") -> Check doc | S18: {=_xlfn.XLOOKUP(Tabela3[[#This Row],[LOTE]],VALUE(Painel_Bancada[Lote]),Painel_Bancada[Data Programada],"")} | T18: =_xlfn.XLOOKUP(Tabela3[[#This Row],[LOTE]],'PAINEL - GERAL'!F:F,'PAINEL - GERAL'!C:C,"")
B19: 5001 | C19: 461168 | D19: GENU PECTIN LM-HC-30 CS | E19: 90002026 | H19: PCP | I19: 46225 | K19: 46225 | L19: 46218 | M19: =K19+8 -> 46233 | N19: =IF(WEEKDAY(K19,2)=4,K19+11,IF(WEEKDAY(K19,2)=5,K19+11,K19+10)) -> 46235 | O19: =_xlfn.XLOOKUP(Tabela3[[#This Row],[LOTE]],QUARENTENA!D:D,QUARENTENA!I:I,"") -> DU APROVADO | P19: atraso de vigencia de documentação | Q19: =IF(_xlfn.XLOOKUP(E19,QUARENTENA!D:D,QUARENTENA!M:M,"")="","",_xlfn.XLOOKUP(E19,QUARENTENA!D:D,QUARENTENA!M:M,"")) -> 46277 | R19: =_xlfn.XLOOKUP(C19,'PARTICULARIDADES AUXILIAR '!A:A,'PARTICULARIDADES AUXILIAR '!C:C,"") | S19: {=_xlfn.XLOOKUP(Tabela3[[#This Row],[LOTE]],VALUE(Painel_Bancada[Lote]),Painel_Bancada[Data Programada],"")} -> 46242 | T19: =_xlfn.XLOOKUP(Tabela3[[#This Row],[LOTE]],'PAINEL - GERAL'!F:F,'PAINEL - GERAL'!C:C,"")
B20: 5001 | C20: 439084 | D20: A CLORID DE CICLOBENZAPRINA MTC | E20: 20372021 | F20: NA | G20: NA | H20: REVALIDAÇÃO | I20: =Tabela3[[#This Row],[CENTRO (Centro PARA)]]&Tabela3[[#This Row],[CODIGO (Código PARA)]]&Tabela3[[#This Row],[LOTE]]&Tabela3[[#This Row],[DESCRIÇÃO]]&Tabela3[[#This Row],[id]] -> 500143908420372021A CLORID DE CICLOBENZAPRINA MTC | K20: 46227 | L20: 46220 | M20: =K20+8 -> 46235 | N20: =IF(WEEKDAY(K20,2)=4,K20+11,IF(WEEKDAY(K20,2)=5,K20+11,K20+10)) -> 46238 | O20: DU APROVADO | Q20: 46279 | R20: =_xlfn.XLOOKUP(C20,'PARTICULARIDADES AUXILIAR '!A:A,'PARTICULARIDADES AUXILIAR '!C:C,"") | S20: {=_xlfn.XLOOKUP(Tabela3[[#This Row],[LOTE]],VALUE(Painel_Bancada[Lote]),Painel_Bancada[Data Programada],"")} -> 46255 | T20: =_xlfn.XLOOKUP(Tabela3[[#This Row],[LOTE]],'PAINEL - GERAL'!F:F,'PAINEL - GERAL'!C:C,"")
B21: 5001 | C21: 438013 | D21: E CETILFOSFATO DE POTASSIO MTCD | E21: 152392026 | F21: 400 | G21: NA | H21: OPORTUNIDADE | I21: =Tabela3[[#This Row],[CENTRO (Centro PARA)]]&Tabela3[[#This Row],[CODIGO (Código PARA)]]&Tabela3[[#This Row],[LOTE]]&Tabela3[[#This Row],[DESCRIÇÃO]]&Tabela3[[#This Row],[id]] -> 5001438013152392026E CETILFOSFATO DE POTASSIO MTCD | K21: 46227 | L21: 46220 | M21: =K21+8 -> 46235 | N21: =IF(WEEKDAY(K21,2)=4,K21+11,IF(WEEKDAY(K21,2)=5,K21+11,K21+10)) -> 46238 | O21: =_xlfn.XLOOKUP(Tabela3[[#This Row],[LOTE]],QUARENTENA!D:D,QUARENTENA!I:I,"") -> DU APROVADO | P21: MATERIAL EM TERCEIRO | Q21: =IF(_xlfn.XLOOKUP(E21,QUARENTENA!D:D,QUARENTENA!M:M,"")="","",_xlfn.XLOOKUP(E21,QUARENTENA!D:D,QUARENTENA!M:M,"")) -> 46286 | R21: =_xlfn.XLOOKUP(C21,'PARTICULARIDADES AUXILIAR '!A:A,'PARTICULARIDADES AUXILIAR '!C:C,"") -> Check doc | S21: {=_xlfn.XLOOKUP(Tabela3[[#This Row],[LOTE]],VALUE(Painel_Bancada[Lote]),Painel_Bancada[Data Programada],"")} | T21: =_xlfn.XLOOKUP(Tabela3[[#This Row],[LOTE]],'PAINEL - GERAL'!F:F,'PAINEL - GERAL'!C:C,"")
B22: 5001 | C22: 438013 | D22: E CETILFOSFATO DE POTASSIO MTCD | E22: 152402026 | F22: 300 | G22: NA | H22: OPORTUNIDADE | I22: =Tabela3[[#This Row],[CENTRO (Centro PARA)]]&Tabela3[[#This Row],[CODIGO (Código PARA)]]&Tabela3[[#This Row],[LOTE]]&Tabela3[[#This Row],[DESCRIÇÃO]]&Tabela3[[#This Row],[id]] -> 5001438013152402026E CETILFOSFATO DE POTASSIO MTCD | K22: 46227 | L22: 46220 | M22: =K22+8 -> 46235 | N22: =IF(WEEKDAY(K22,2)=4,K22+11,IF(WEEKDAY(K22,2)=5,K22+11,K22+10)) -> 46238 | O22: =_xlfn.XLOOKUP(Tabela3[[#This Row],[LOTE]],QUARENTENA!D:D,QUARENTENA!I:I,"") -> DU APROVADO | P22: MATERIAL EM TERCEIRO | Q22: =IF(_xlfn.XLOOKUP(E22,QUARENTENA!D:D,QUARENTENA!M:M,"")="","",_xlfn.XLOOKUP(E22,QUARENTENA!D:D,QUARENTENA!M:M,"")) -> 46286 | R22: =_xlfn.XLOOKUP(C22,'PARTICULARIDADES AUXILIAR '!A:A,'PARTICULARIDADES AUXILIAR '!C:C,"") -> Check doc | S22: {=_xlfn.XLOOKUP(Tabela3[[#This Row],[LOTE]],VALUE(Painel_Bancada[Lote]),Painel_Bancada[Data Programada],"")} | T22: =_xlfn.XLOOKUP(Tabela3[[#This Row],[LOTE]],'PAINEL - GERAL'!F:F,'PAINEL - GERAL'!C:C,"")
B23: 5001 | C23: 605630 | D23: TRIGLICERIDEO ACIDO CAPRILICO CAPRICO | E23: 67542026 | F23: 113 | G23: 46239 | H23: PCP | I23: =Tabela3[[#This Row],[CENTRO (Centro PARA)]]&Tabela3[[#This Row],[CODIGO (Código PARA)]]&Tabela3[[#This Row],[LOTE]]&Tabela3[[#This Row],[DESCRIÇÃO]]&Tabela3[[#This Row],[id]] -> 500160563067542026TRIGLICERIDEO ACIDO CAPRILICO CAPRICO | K23: 46227 | L23: 46220 | M23: =K23+8 -> 46235 | N23: =IF(WEEKDAY(K23,2)=4,K23+11,IF(WEEKDAY(K23,2)=5,K23+11,K23+10)) -> 46238 | O23: =_xlfn.XLOOKUP(Tabela3[[#This Row],[LOTE]],QUARENTENA!D:D,QUARENTENA!I:I,"") -> DU APROVADO | P23: ag. Plano SDA - prev. 29/07 | Q23: =IF(_xlfn.XLOOKUP(E23,QUARENTENA!D:D,QUARENTENA!M:M,"")="","",_xlfn.XLOOKUP(E23,QUARENTENA!D:D,QUARENTENA!M:M,"")) -> 46290 | R23: =_xlfn.XLOOKUP(C23,'PARTICULARIDADES AUXILIAR '!A:A,'PARTICULARIDADES AUXILIAR '!C:C,"") | S23: {=_xlfn.XLOOKUP(Tabela3[[#This Row],[LOTE]],VALUE(Painel_Bancada[Lote]),Painel_Bancada[Data Programada],"")} -> 46241 | T23: =_xlfn.XLOOKUP(Tabela3[[#This Row],[LOTE]],'PAINEL - GERAL'!F:F,'PAINEL - GERAL'!C:C,"")
B24: 5001 | C24: 459975 | D24: OLEO RICINO HIDROGENADO PEG 40 | E24: 21582026 | G24: 46240 | H24: PCP | I24: =Tabela3[[#This Row],[CENTRO (Centro PARA)]]&Tabela3[[#This Row],[CODIGO (Código PARA)]]&Tabela3[[#This Row],[LOTE]]&Tabela3[[#This Row],[DESCRIÇÃO]]&Tabela3[[#This Row],[id]] -> 500145997521582026OLEO RICINO HIDROGENADO PEG 40 | K24: 46230 | L24: 46223 | M24: =K24+8 -> 46238 | N24: =IF(WEEKDAY(K24,2)=4,K24+11,IF(WEEKDAY(K24,2)=5,K24+11,K24+10)) -> 46240 | O24: =_xlfn.XLOOKUP(Tabela3[[#This Row],[LOTE]],QUARENTENA!D:D,QUARENTENA!I:I,"") -> DU APROVADO | P24: não tem plano SAP - SEM PREVI | Q24: =IF(_xlfn.XLOOKUP(E24,QUARENTENA!D:D,QUARENTENA!M:M,"")="","",_xlfn.XLOOKUP(E24,QUARENTENA!D:D,QUARENTENA!M:M,"")) -> 46279 | R24: =_xlfn.XLOOKUP(C24,'PARTICULARIDADES AUXILIAR '!A:A,'PARTICULARIDADES AUXILIAR '!C:C,"") | S24: {=_xlfn.XLOOKUP(Tabela3[[#This Row],[LOTE]],VALUE(Painel_Bancada[Lote]),Painel_Bancada[Data Programada],"")} -> 46274 | T24: =_xlfn.XLOOKUP(Tabela3[[#This Row],[LOTE]],'PAINEL - GERAL'!F:F,'PAINEL - GERAL'!C:C,"")
B25: 5001 | C25: 478553 | D25: PARACETAMOL QF3 | E25: 56902026 | G25: NA | H25: OPORTUNIDADE | I25: =Tabela3[[#This Row],[CENTRO (Centro PARA)]]&Tabela3[[#This Row],[CODIGO (Código PARA)]]&Tabela3[[#This Row],[LOTE]]&Tabela3[[#This Row],[DESCRIÇÃO]]&Tabela3[[#This Row],[id]] -> 500147855356902026PARACETAMOL QF3 | K25: 46230 | M25: =K25+8 -> 46238 | N25: =IF(WEEKDAY(K25,2)=4,K25+11,IF(WEEKDAY(K25,2)=5,K25+11,K25+10)) -> 46240 | O25: =_xlfn.XLOOKUP(Tabela3[[#This Row],[LOTE]],QUARENTENA!D:D,QUARENTENA!I:I,"") -> DU APROVADO | P25: MATERIAL EM TERCEIRO | Q25: =IF(_xlfn.XLOOKUP(E25,QUARENTENA!D:D,QUARENTENA!M:M,"")="","",_xlfn.XLOOKUP(E25,QUARENTENA!D:D,QUARENTENA!M:M,"")) -> 46267 | R25: =_xlfn.XLOOKUP(C25,'PARTICULARIDADES AUXILIAR '!A:A,'PARTICULARIDADES AUXILIAR '!C:C,"") -> Polícia Federal | S25: {=_xlfn.XLOOKUP(Tabela3[[#This Row],[LOTE]],VALUE(Painel_Bancada[Lote]),Painel_Bancada[Data Programada],"")} -> 46261 | T25: =_xlfn.XLOOKUP(Tabela3[[#This Row],[LOTE]],'PAINEL - GERAL'!F:F,'PAINEL - GERAL'!C:C,"")
B26: 5001 | C26: 463406 | D26: CASSIA FISTULA EXTRATO SECO 0,03-0,06% | E26: 135962026 | F26: 150 | G26: NA | H26: OPORTUNIDADE | I26: =Tabela3[[#This Row],[CENTRO (Centro PARA)]]&Tabela3[[#This Row],[CODIGO (Código PARA)]]&Tabela3[[#This Row],[LOTE]]&Tabela3[[#This Row],[DESCRIÇÃO]]&Tabela3[[#This Row],[id]] -> 5001463406135962026CASSIA FISTULA EXTRATO SECO 0,03-0,06% | K26: 46231 | L26: 46224 | M26: =K26+8 -> 46239 | N26: =IF(WEEKDAY(K26,2)=4,K26+11,IF(WEEKDAY(K26,2)=5,K26+11,K26+10)) -> 46241 | O26: =_xlfn.XLOOKUP(Tabela3[[#This Row],[LOTE]],QUARENTENA!D:D,QUARENTENA!I:I,"") -> DU REPROVADO | Q26: =IF(_xlfn.XLOOKUP(E26,QUARENTENA!D:D,QUARENTENA!M:M,"")="","",_xlfn.XLOOKUP(E26,QUARENTENA!D:D,QUARENTENA!M:M,"")) -> 46282 | R26: =_xlfn.XLOOKUP(C26,'PARTICULARIDADES AUXILIAR '!A:A,'PARTICULARIDADES AUXILIAR '!C:C,"") -> Pesticidas/ Aflatoxinas - EM TERCEIRO | S26: {=_xlfn.XLOOKUP(Tabela3[[#This Row],[LOTE]],VALUE(Painel_Bancada[Lote]),Painel_Bancada[Data Programada],"")} -> 46240 | T26: =_xlfn.XLOOKUP(Tabela3[[#This Row],[LOTE]],'PAINEL - GERAL'!F:F,'PAINEL - GERAL'!C:C,"")
B27: 5001 | C27: 459976 | D27: MONOOLEATO SORBITANO 80 | E27: 121212026 | F27: 189.6 | G27: 46241 | H27: PCP | I27: =Tabela3[[#This Row],[CENTRO (Centro PARA)]]&Tabela3[[#This Row],[CODIGO (Código PARA)]]&Tabela3[[#This Row],[LOTE]]&Tabela3[[#This Row],[DESCRIÇÃO]]&Tabela3[[#This Row],[id]] -> 5001459976121212026MONOOLEATO SORBITANO 80 | K27: 46231 | L27: 46224 | M27: =K27+8 -> 46239 | N27: =IF(WEEKDAY(K27,2)=4,K27+11,IF(WEEKDAY(K27,2)=5,K27+11,K27+10)) -> 46241 | O27: =_xlfn.XLOOKUP(Tabela3[[#This Row],[LOTE]],QUARENTENA!D:D,QUARENTENA!I:I,"") -> INVESTIGAÇÃO P&D | P27: não tem plano SAP, sem método vigente | Q27: =IF(_xlfn.XLOOKUP(E27,QUARENTENA!D:D,QUARENTENA!M:M,"")="","",_xlfn.XLOOKUP(E27,QUARENTENA!D:D,QUARENTENA!M:M,"")) | R27: =_xlfn.XLOOKUP(C27,'PARTICULARIDADES AUXILIAR '!A:A,'PARTICULARIDADES AUXILIAR '!C:C,"") | S27: {=_xlfn.XLOOKUP(Tabela3[[#This Row],[LOTE]],VALUE(Painel_Bancada[Lote]),Painel_Bancada[Data Programada],"")} -> 46270 | T27: =_xlfn.XLOOKUP(Tabela3[[#This Row],[LOTE]],'PAINEL - GERAL'!F:F,'PAINEL - GERAL'!C:C,"")
B28: 5001 | C28: 422463 | D28: TEREBINTINA | E28: 146332026 | F28: 1980 | G28: NA | H28: OPORTUNIDADE | I28: =Tabela3[[#This Row],[CENTRO (Centro PARA)]]&Tabela3[[#This Row],[CODIGO (Código PARA)]]&Tabela3[[#This Row],[LOTE]]&Tabela3[[#This Row],[DESCRIÇÃO]]&Tabela3[[#This Row],[id]] -> 5001422463146332026TEREBINTINA | K28: 46234 | L28: 46227 | M28: =K28+8 -> 46242 | N28: =IF(WEEKDAY(K28,2)=4,K28+11,IF(WEEKDAY(K28,2)=5,K28+11,K28+10)) -> 46245 | O28: =_xlfn.XLOOKUP(Tabela3[[#This Row],[LOTE]],QUARENTENA!D:D,QUARENTENA!I:I,"") -> INVESTIGAÇÃO P&D | Q28: =IF(_xlfn.XLOOKUP(E28,QUARENTENA!D:D,QUARENTENA!M:M,"")="","",_xlfn.XLOOKUP(E28,QUARENTENA!D:D,QUARENTENA!M:M,"")) | R28: =_xlfn.XLOOKUP(C28,'PARTICULARIDADES AUXILIAR '!A:A,'PARTICULARIDADES AUXILIAR '!C:C,"") -> Inflamável | S28: {=_xlfn.XLOOKUP(Tabela3[[#This Row],[LOTE]],VALUE(Painel_Bancada[Lote]),Painel_Bancada[Data Programada],"")} -> 46238 | T28: =_xlfn.XLOOKUP(Tabela3[[#This Row],[LOTE]],'PAINEL - GERAL'!F:F,'PAINEL - GERAL'!C:C,"")
B29: 5001 | C29: 422364 | D29: CITRATO COLINA | E29: 78782026 | F29: 400 | G29: NA | H29: OPORTUNIDADE | I29: =Tabela3[[#This Row],[CENTRO (Centro PARA)]]&Tabela3[[#This Row],[CODIGO (Código PARA)]]&Tabela3[[#This Row],[LOTE]]&Tabela3[[#This Row],[DESCRIÇÃO]]&Tabela3[[#This Row],[id]] -> 500142236478782026CITRATO COLINA | K29: 46238 | L29: 46231 | M29: =K29+8 -> 46246 | N29: =IF(WEEKDAY(K29,2)=4,K29+11,IF(WEEKDAY(K29,2)=5,K29+11,K29+10)) -> 46248 | O29: =_xlfn.XLOOKUP(Tabela3[[#This Row],[LOTE]],QUARENTENA!D:D,QUARENTENA!I:I,"") -> DU APROVADO | P29: MATERIAL EM TERCEIRO | Q29: =IF(_xlfn.XLOOKUP(E29,QUARENTENA!D:D,QUARENTENA!M:M,"")="","",_xlfn.XLOOKUP(E29,QUARENTENA!D:D,QUARENTENA!M:M,"")) -> 46280 | R29: =_xlfn.XLOOKUP(C29,'PARTICULARIDADES AUXILIAR '!A:A,'PARTICULARIDADES AUXILIAR '!C:C,"") -> PF - repouso 24 horas | S29: {=_xlfn.XLOOKUP(Tabela3[[#This Row],[LOTE]],VALUE(Painel_Bancada[Lote]),Painel_Bancada[Data Programada],"")} -> 46275 | T29: =_xlfn.XLOOKUP(Tabela3[[#This Row],[LOTE]],'PAINEL - GERAL'!F:F,'PAINEL - GERAL'!C:C,"")
B30: 5001 | C30: 422364 | D30: CITRATO COLINA | E30: 78792026 | F30: 800 | G30: NA | H30: OPORTUNIDADE | I30: =Tabela3[[#This Row],[CENTRO (Centro PARA)]]&Tabela3[[#This Row],[CODIGO (Código PARA)]]&Tabela3[[#This Row],[LOTE]]&Tabela3[[#This Row],[DESCRIÇÃO]]&Tabela3[[#This Row],[id]] -> 500142236478792026CITRATO COLINA | K30: 46238 | L30: 46231 | M30: =K30+8 -> 46246 | N30: =IF(WEEKDAY(K30,2)=4,K30+11,IF(WEEKDAY(K30,2)=5,K30+11,K30+10)) -> 46248 | O30: =_xlfn.XLOOKUP(Tabela3[[#This Row],[LOTE]],QUARENTENA!D:D,QUARENTENA!I:I,"") -> DU APROVADO | P30: MATERIAL EM TERCEIRO | Q30: =IF(_xlfn.XLOOKUP(E30,QUARENTENA!D:D,QUARENTENA!M:M,"")="","",_xlfn.XLOOKUP(E30,QUARENTENA!D:D,QUARENTENA!M:M,"")) -> 46280 | R30: =_xlfn.XLOOKUP(C30,'PARTICULARIDADES AUXILIAR '!A:A,'PARTICULARIDADES AUXILIAR '!C:C,"") -> PF - repouso 24 horas | S30: {=_xlfn.XLOOKUP(Tabela3[[#This Row],[LOTE]],VALUE(Painel_Bancada[Lote]),Painel_Bancada[Data Programada],"")} -> 46275 | T30: =_xlfn.XLOOKUP(Tabela3[[#This Row],[LOTE]],'PAINEL - GERAL'!F:F,'PAINEL - GERAL'!C:C,"")
B31: 2017 | C31: 210116 | D31: VITAMINA C | E31: 4292026 | F31: 2900 | G31: 46254 | H31: PCP | I31: =Tabela3[[#This Row],[CENTRO (Centro PARA)]]&Tabela3[[#This Row],[CODIGO (Código PARA)]]&Tabela3[[#This Row],[LOTE]]&Tabela3[[#This Row],[DESCRIÇÃO]]&Tabela3[[#This Row],[id]] -> 20172101164292026VITAMINA C | K31: 46244 | L31: 46238 | M31: =K31+8 -> 46252 | N31: =IF(WEEKDAY(K31,2)=4,K31+11,IF(WEEKDAY(K31,2)=5,K31+11,K31+10)) -> 46254 | O31: DU APROVADO | Q31: 46239 | R31: =_xlfn.XLOOKUP(C31,'PARTICULARIDADES AUXILIAR '!A:A,'PARTICULARIDADES AUXILIAR '!C:C,"") -> Check doc | S31: {=_xlfn.XLOOKUP(Tabela3[[#This Row],[LOTE]],VALUE(Painel_Bancada[Lote]),Painel_Bancada[Data Programada],"")} | T31: =_xlfn.XLOOKUP(Tabela3[[#This Row],[LOTE]],'PAINEL - GERAL'!F:F,'PAINEL - GERAL'!C:C,"")
B32: 5001 | C32: 442832 | D32: HPMC K100 LV | E32: 146312026 | F32: 1376 | G32: 46254 | H32: PCP | I32: =Tabela3[[#This Row],[CENTRO (Centro PARA)]]&Tabela3[[#This Row],[CODIGO (Código PARA)]]&Tabela3[[#This Row],[LOTE]]&Tabela3[[#This Row],[DESCRIÇÃO]]&Tabela3[[#This Row],[id]] -> 5001442832146312026HPMC K100 LV | K32: 46244 | L32: 46238 | M32: =K32+8 -> 46252 | N32: =IF(WEEKDAY(K32,2)=4,K32+11,IF(WEEKDAY(K32,2)=5,K32+11,K32+10)) -> 46254 | O32: =_xlfn.XLOOKUP(Tabela3[[#This Row],[LOTE]],QUARENTENA!D:D,QUARENTENA!I:I,"") -> DU APROVADO | Q32: =IF(_xlfn.XLOOKUP(E32,QUARENTENA!D:D,QUARENTENA!M:M,"")="","",_xlfn.XLOOKUP(E32,QUARENTENA!D:D,QUARENTENA!M:M,"")) -> 46252 | R32: =_xlfn.XLOOKUP(C32,'PARTICULARIDADES AUXILIAR '!A:A,'PARTICULARIDADES AUXILIAR '!C:C,"") | S32: {=_xlfn.XLOOKUP(Tabela3[[#This Row],[LOTE]],VALUE(Painel_Bancada[Lote]),Painel_Bancada[Data Programada],"")} -> 46245 | T32: =_xlfn.XLOOKUP(Tabela3[[#This Row],[LOTE]],'PAINEL - GERAL'!F:F,'PAINEL - GERAL'!C:C,"")
B33: 5001 | C33: 422376 | D33: CLORIDRATO NAFAZOLINA | E33: 23662026 | F33: 49.943 | G33: 46254 | H33: PCP | I33: =Tabela3[[#This Row],[CENTRO (Centro PARA)]]&Tabela3[[#This Row],[CODIGO (Código PARA)]]&Tabela3[[#This Row],[LOTE]]&Tabela3[[#This Row],[DESCRIÇÃO]]&Tabela3[[#This Row],[id]] -> 500142237623662026CLORIDRATO NAFAZOLINA | K33: 46244 | L33: 46238 | M33: =K33+8 -> 46252 | N33: =IF(WEEKDAY(K33,2)=4,K33+11,IF(WEEKDAY(K33,2)=5,K33+11,K33+10)) -> 46254 | O33: =_xlfn.XLOOKUP(Tabela3[[#This Row],[LOTE]],QUARENTENA!D:D,QUARENTENA!I:I,"") -> DU APROVADO | Q33: =IF(_xlfn.XLOOKUP(E33,QUARENTENA!D:D,QUARENTENA!M:M,"")="","",_xlfn.XLOOKUP(E33,QUARENTENA!D:D,QUARENTENA!M:M,"")) -> 46238 | R33: =_xlfn.XLOOKUP(C33,'PARTICULARIDADES AUXILIAR '!A:A,'PARTICULARIDADES AUXILIAR '!C:C,"") | S33: {=_xlfn.XLOOKUP(Tabela3[[#This Row],[LOTE]],VALUE(Painel_Bancada[Lote]),Painel_Bancada[Data Programada],"")} -> 46599 | T33: =_xlfn.XLOOKUP(Tabela3[[#This Row],[LOTE]],'PAINEL - GERAL'!F:F,'PAINEL - GERAL'!C:C,"")
B34: 5001 | C34: 410034 | D34: CELULOSE MICROCRISTALINA MC102 NEO | E34: 151662026 | F34: 2625 | G34: 46254 | H34: PCP | I34: =Tabela3[[#This Row],[CENTRO (Centro PARA)]]&Tabela3[[#This Row],[CODIGO (Código PARA)]]&Tabela3[[#This Row],[LOTE]]&Tabela3[[#This Row],[DESCRIÇÃO]]&Tabela3[[#This Row],[id]] -> 5001410034151662026CELULOSE MICROCRISTALINA MC102 NEO | K34: 46244 | L34: 46238 | M34: =K34+8 -> 46252 | N34: =IF(WEEKDAY(K34,2)=4,K34+11,IF(WEEKDAY(K34,2)=5,K34+11,K34+10)) -> 46254 | O34: =_xlfn.XLOOKUP(Tabela3[[#This Row],[LOTE]],QUARENTENA!D:D,QUARENTENA!I:I,"") -> DU APROVADO | Q34: =IF(_xlfn.XLOOKUP(E34,QUARENTENA!D:D,QUARENTENA!M:M,"")="","",_xlfn.XLOOKUP(E34,QUARENTENA!D:D,QUARENTENA!M:M,"")) -> 46252 | R34: =_xlfn.XLOOKUP(C34,'PARTICULARIDADES AUXILIAR '!A:A,'PARTICULARIDADES AUXILIAR '!C:C,"") | S34: {=_xlfn.XLOOKUP(Tabela3[[#This Row],[LOTE]],VALUE(Painel_Bancada[Lote]),Painel_Bancada[Data Programada],"")} | T34: =_xlfn.XLOOKUP(Tabela3[[#This Row],[LOTE]],'PAINEL - GERAL'!F:F,'PAINEL - GERAL'!C:C,"")
B35: 5001 | C35: 439080 | D35: E TALCO USP MTC | E35: 156342026 | F35: 600 | G35: 46254 | H35: PCP | I35: =Tabela3[[#This Row],[CENTRO (Centro PARA)]]&Tabela3[[#This Row],[CODIGO (Código PARA)]]&Tabela3[[#This Row],[LOTE]]&Tabela3[[#This Row],[DESCRIÇÃO]]&Tabela3[[#This Row],[id]] -> 5001439080156342026E TALCO USP MTC | K35: 46244 | L35: 46238 | M35: =K35+8 -> 46252 | N35: =IF(WEEKDAY(K35,2)=4,K35+11,IF(WEEKDAY(K35,2)=5,K35+11,K35+10)) -> 46254 | O35: =_xlfn.XLOOKUP(Tabela3[[#This Row],[LOTE]],QUARENTENA!D:D,QUARENTENA!I:I,"") -> DU APROVADO | Q35: =IF(_xlfn.XLOOKUP(E35,QUARENTENA!D:D,QUARENTENA!M:M,"")="","",_xlfn.XLOOKUP(E35,QUARENTENA!D:D,QUARENTENA!M:M,"")) -> 46254 | R35: =_xlfn.XLOOKUP(C35,'PARTICULARIDADES AUXILIAR '!A:A,'PARTICULARIDADES AUXILIAR '!C:C,"") -> Alumínio; Cálcio; Magnésio | S35: {=_xlfn.XLOOKUP(Tabela3[[#This Row],[LOTE]],VALUE(Painel_Bancada[Lote]),Painel_Bancada[Data Programada],"")} -> 46251 | T35: =_xlfn.XLOOKUP(Tabela3[[#This Row],[LOTE]],'PAINEL - GERAL'!F:F,'PAINEL - GERAL'!C:C,"")
B36: 5001 | C36: 463348 | D36: CRODAMOL GTCC- LQ_(BR) | E36: 133342026 | F36: 179.967 | G36: 46254 | H36: PCP | I36: =Tabela3[[#This Row],[CENTRO (Centro PARA)]]&Tabela3[[#This Row],[CODIGO (Código PARA)]]&Tabela3[[#This Row],[LOTE]]&Tabela3[[#This Row],[DESCRIÇÃO]]&Tabela3[[#This Row],[id]] -> 5001463348133342026CRODAMOL GTCC- LQ_(BR) | K36: 46244 | L36: 46238 | M36: =K36+8 -> 46252 | N36: =IF(WEEKDAY(K36,2)=4,K36+11,IF(WEEKDAY(K36,2)=5,K36+11,K36+10)) -> 46254 | O36: DU APROVADO | Q36: 46218 | R36: =_xlfn.XLOOKUP(C36,'PARTICULARIDADES AUXILIAR '!A:A,'PARTICULARIDADES AUXILIAR '!C:C,"") -> Check doc | S36: {=_xlfn.XLOOKUP(Tabela3[[#This Row],[LOTE]],VALUE(Painel_Bancada[Lote]),Painel_Bancada[Data Programada],"")} | T36: =_xlfn.XLOOKUP(Tabela3[[#This Row],[LOTE]],'PAINEL - GERAL'!F:F,'PAINEL - GERAL'!C:C,"")
B37: 5001 | C37: 465107 | D37: HESPERIDINA QF3 | E37: 171382026 | F37: 1000 | G37: 46254 | H37: PCP | I37: =Tabela3[[#This Row],[CENTRO (Centro PARA)]]&Tabela3[[#This Row],[CODIGO (Código PARA)]]&Tabela3[[#This Row],[LOTE]]&Tabela3[[#This Row],[DESCRIÇÃO]]&Tabela3[[#This Row],[id]] -> 5001465107171382026HESPERIDINA QF3 | K37: 46244 | L37: 46238 | M37: =K37+8 -> 46252 | N37: =IF(WEEKDAY(K37,2)=4,K37+11,IF(WEEKDAY(K37,2)=5,K37+11,K37+10)) -> 46254 | O37: =_xlfn.XLOOKUP(Tabela3[[#This Row],[LOTE]],QUARENTENA!D:D,QUARENTENA!I:I,"") -> DU APROVADO | P37: amostragem - atraso de entrega de amostra / RO | Q37: =IF(_xlfn.XLOOKUP(E37,QUARENTENA!D:D,QUARENTENA!M:M,"")="","",_xlfn.XLOOKUP(E37,QUARENTENA!D:D,QUARENTENA!M:M,"")) -> 46256 | R37: =_xlfn.XLOOKUP(C37,'PARTICULARIDADES AUXILIAR '!A:A,'PARTICULARIDADES AUXILIAR '!C:C,"") | S37: {=_xlfn.XLOOKUP(Tabela3[[#This Row],[LOTE]],VALUE(Painel_Bancada[Lote]),Painel_Bancada[Data Programada],"")} -> 46253 | T37: =_xlfn.XLOOKUP(Tabela3[[#This Row],[LOTE]],'PAINEL - GERAL'!F:F,'PAINEL - GERAL'!C:C,"")
B38: 5001 | C38: 470118 | D38: CLORETO DE SODIO 2 | E38: 150602026 | F38: 4575 | G38: 46254 | H38: PCP | I38: =Tabela3[[#This Row],[CENTRO (Centro PARA)]]&Tabela3[[#This Row],[CODIGO (Código PARA)]]&Tabela3[[#This Row],[LOTE]]&Tabela3[[#This Row],[DESCRIÇÃO]]&Tabela3[[#This Row],[id]] -> 5001470118150602026CLORETO DE SODIO 2 | K38: 46244 | L38: 46238 | M38: =K38+8 -> 46252 | N38: =IF(WEEKDAY(K38,2)=4,K38+11,IF(WEEKDAY(K38,2)=5,K38+11,K38+10)) -> 46254 | O38: =_xlfn.XLOOKUP(Tabela3[[#This Row],[LOTE]],QUARENTENA!D:D,QUARENTENA!I:I,"") -> DU APROVADO | Q38: =IF(_xlfn.XLOOKUP(E38,QUARENTENA!D:D,QUARENTENA!M:M,"")="","",_xlfn.XLOOKUP(E38,QUARENTENA!D:D,QUARENTENA!M:M,"")) -> 46290 | R38: =_xlfn.XLOOKUP(C38,'PARTICULARIDADES AUXILIAR '!A:A,'PARTICULARIDADES AUXILIAR '!C:C,"") -> ID - repouso 24 horas | S38: {=_xlfn.XLOOKUP(Tabela3[[#This Row],[LOTE]],VALUE(Painel_Bancada[Lote]),Painel_Bancada[Data Programada],"")} -> 46245 | T38: =_xlfn.XLOOKUP(Tabela3[[#This Row],[LOTE]],'PAINEL - GERAL'!F:F,'PAINEL - GERAL'!C:C,"")
B39: 5001 | C39: 470911 | D39: COPOVIDONA BAIXO TEOR PEROXIDO | E39: 133762026 | F39: 38.56 | G39: 46254 | H39: PCP | I39: =Tabela3[[#This Row],[CENTRO (Centro PARA)]]&Tabela3[[#This Row],[CODIGO (Código PARA)]]&Tabela3[[#This Row],[LOTE]]&Tabela3[[#This Row],[DESCRIÇÃO]]&Tabela3[[#This Row],[id]] -> 5001470911133762026COPOVIDONA BAIXO TEOR PEROXIDO | K39: 46244 | L39: 46238 | M39: =K39+8 -> 46252 | N39: =IF(WEEKDAY(K39,2)=4,K39+11,IF(WEEKDAY(K39,2)=5,K39+11,K39+10)) -> 46254 | O39: =_xlfn.XLOOKUP(Tabela3[[#This Row],[LOTE]],QUARENTENA!D:D,QUARENTENA!I:I,"") -> AG. AMOSTRA | P39: NÃO TEM MÉTODO VIGENTE | Q39: =IF(_xlfn.XLOOKUP(E39,QUARENTENA!D:D,QUARENTENA!M:M,"")="","",_xlfn.XLOOKUP(E39,QUARENTENA!D:D,QUARENTENA!M:M,"")) | R39: =_xlfn.XLOOKUP(C39,'PARTICULARIDADES AUXILIAR '!A:A,'PARTICULARIDADES AUXILIAR '!C:C,"") | S39: {=_xlfn.XLOOKUP(Tabela3[[#This Row],[LOTE]],VALUE(Painel_Bancada[Lote]),Painel_Bancada[Data Programada],"")} | T39: =_xlfn.XLOOKUP(Tabela3[[#This Row],[LOTE]],'PAINEL - GERAL'!F:F,'PAINEL - GERAL'!C:C,"")
B40: 5001 | C40: 410072 | D40: BASE POLIETILENO PETROLATO NEO | E40: 134222026 | F40: 1700 | G40: 46254 | H40: OPORTUNIDADE | I40: =Tabela3[[#This Row],[CENTRO (Centro PARA)]]&Tabela3[[#This Row],[CODIGO (Código PARA)]]&Tabela3[[#This Row],[LOTE]]&Tabela3[[#This Row],[DESCRIÇÃO]]&Tabela3[[#This Row],[id]] -> 5001410072134222026BASE POLIETILENO PETROLATO NEO | K40: 46244 | L40: 46238 | M40: =K40+8 -> 46252 | N40: =IF(WEEKDAY(K40,2)=4,K40+11,IF(WEEKDAY(K40,2)=5,K40+11,K40+10)) -> 46254 | O40: =_xlfn.XLOOKUP(Tabela3[[#This Row],[LOTE]],QUARENTENA!D:D,QUARENTENA!I:I,"") -> DU APROVADO | P40: MATERIAL EM TERCEIRO | Q40: =IF(_xlfn.XLOOKUP(E40,QUARENTENA!D:D,QUARENTENA!M:M,"")="","",_xlfn.XLOOKUP(E40,QUARENTENA!D:D,QUARENTENA!M:M,"")) -> 46276 | R40: =_xlfn.XLOOKUP(C40,'PARTICULARIDADES AUXILIAR '!A:A,'PARTICULARIDADES AUXILIAR '!C:C,"") | S40: {=_xlfn.XLOOKUP(Tabela3[[#This Row],[LOTE]],VALUE(Painel_Bancada[Lote]),Painel_Bancada[Data Programada],"")} -> 46253 | T40: =_xlfn.XLOOKUP(Tabela3[[#This Row],[LOTE]],'PAINEL - GERAL'!F:F,'PAINEL - GERAL'!C:C,"")
...

Sheet ROTAS E FAMILIAS
A1: *Atualizar a tabela clicando com o botão direito do mouse → Atualizar, para carregar os lotes com comando "P" e consolidar as informações pelo código do material.
A2: VISÃO POR LOTE — FAMÍLIAS QUE CADA LOTE PERCORRE
A4: CODIGO (Código PARA) | B4: DESCRIÇÃO | C4: CONCATENADO | D4: D+8 (-2 dias) | E4: D+8 (-3 dias) | F4: FAM FAST EQUIPAMENTO - UV - Vis | G4: FAM FAST EQUIPAMENTO - IR/NIR | H4: FAM FAST EQUIPAMENTO - DSC/RAIOX/TGA/DRX | I4: FAM FAST - ICP / AA | J4: FAM FAST - BANCADA | K4: FAM EXCIP | L4: FAM IFA | M4: Teste CG | N4: Teste HPLC | O4: Check doc | P4: Qtd Fam.
A5: 210201 | B5: CANFORA | C5: 210201 - CANFORA | Lotes: 182272026 | D+8: 17/09/2026 | Particularidades: PF - repouso 24 horas/ Inflamável | D5: 46280 | E5: 46279 | G5: 1 | L5: 10 | M5: 3 | P5: 3
A6: 210407 | B6: ESSENCIA MOSTARDA | C6: 210407 - ESSENCIA MOSTARDA | Lotes: 211452026 | D+8: 14/10/2026 | Particularidades: Inflamável | D6: 46307 | E6: 46305 | G6: 1 | J6: 6 | P6: 2
A7: 409996 | B7: DIOXIDO DE TITANIO | C7: 409996 - DIOXIDO DE TITANIO | Lotes: 191152026 | D+8: 06/10/2026 | Particularidades: Repouso 12 horas | D7: 46298 | E7: 46298 | K7: 9 | P7: 1
A8: 210794 | B8: TRIACETINA | C8: 210794 - TRIACETINA | Lotes: 164762025 | D+8: 10/10/2026 | Particularidades: Inflamável | D8: 46303 | E8: 46302 | G8: 1 | J8: 9 | P8: 2
A9: 409968 | B9: GLICERINA BI DESTILADA NEO | C9: 409968 - GLICERINA BI DESTILADA NEO | Lotes: 112472026 | D+8: 07/10/2026 | Particularidades: Polícia Civil | D9: 46300 | E9: 46298 | G9: 1 | K9: 12 | M9: 3 | P9: 3
A10: 410015 | B10: CROSCARMELOSE SODICA | C10: 410015 - CROSCARMELOSE SODICA | Lotes: 206422026 | D+8: 07/10/2026 | Particularidades: Glicolato - repouso 24 horas | D10: 46300 | E10: 46298 | F10: 1 | G10: 1 | J10: 14 | M10: 1 | P10: 4
A11: 212228 | B11: POLISORBATO 80 | C11: 212228 - POLISORBATO 80 | Lotes: 17702026 | D+8: 14/10/2026 | Particularidades: Check doc | D11: 46307 | E11: 46305 | O11: 1 | P11: 1
A12: 210962 | B12: CITRATO TRIETILA | C12: 210962 - CITRATO TRIETILA | Lotes: 205942026 | D+8: 14/10/2026 | D12: 46307 | E12: 46305 | G12: 1 | K12: 11 | M12: 1 | P12: 3
A13: 408474 | B13: ULTRATIX P-100 | C13: 408474 - ULTRATIX P-100 | Lotes: 215282026 | D+8: 14/10/2026 | Particularidades: Check doc | D13: 46307 | E13: 46305 | O13: 1 | P13: 1
A14: 409926 | B14: VASELINA BRANCA LIQUIDA NEO | C14: 409926 - VASELINA BRANCA LIQUIDA NEO | Lotes: 214722026 / 214712026 | D+8: 14/10/2026 | D14: 46307 | E14: 46305 | G14: 1 | J14: 7 | P14: 2
A15: 410032 | B15: ESSENCIA BANANA HIDROSS REF 906254 NEO | C15: 410032 - ESSENCIA BANANA HIDROSS REF 906254 NEO | Lotes: 203742026 | D+8: 09/10/2026 | Particularidades: Inflamável | D15: 46302 | E15: 46301 | G15: 1 | J15: 4 | P15: 2
A16: 410033 | B16: CELULOSE MICROCRISTALINA MC101 NEO | C16: 410033 - CELULOSE MICROCRISTALINA MC101 NEO | Lotes: 144152026 | D+8: 10/10/2026 | D16: 46303 | E16: 46302 | G16: 1 | J16: 13 | P16: 2
A17: 410034 | B17: CELULOSE MICROCRISTALINA MC102 NEO | C17: 410034 - CELULOSE MICROCRISTALINA MC102 NEO | Lotes: 154892026 / 154922026 / 178642026 / 154902026 / 178282026 / 178652026 / 154912026 | D+8: 13/10/2026 | D17: 46305 | E17: 46305 | G17: 1 | J17: 13 | P17: 2
A18: 410037 | B18: PROPILPARABENO | C18: 410037 - PROPILPARABENO | Lotes: 121482026 | D+8: 14/10/2026 | Particularidades: PF - 16 horas repouso | D18: 46307 | E18: 46305 | G18: 1 | J18: 5 | M18: 1 | N18: 2 | P18: 4
A19: 410038 | B19: HPMC/POLIETILENOGLICOL | C19: 410038 - HPMC/POLIETILENOGLICOL | Lotes: 48642026 / 48652026 / 48662026 / 200452026 | D+8: 22/09/2026 | D19: 46284 | E19: 46284 | G19: 2 | J19: 9 | P19: 2
A20: 410041 | B20: PVP K30 POLIVINILPIRROLIDONA NEO | C20: 410041 - PVP K30 POLIVINILPIRROLIDONA NEO | Lotes: 203852026 / 169402026 / 199912026 | D+8: 06/10/2026 | D20: 46298 | E20: 46298 | F20: 2 | G20: 1 | K20: 12 | N20: 3 | P20: 4
A21: 410043 | B21: PARAFINA BRANCA NEO | C21: 410043 - PARAFINA BRANCA NEO | Lotes: 204292026 | D+8: 10/10/2026 | D21: 46303 | E21: 46302 | F21: 1 | G21: 1 | J21: 8 | P21: 3
A22: 410050 | B22: FOSFATO DE CALCIO DIBAS EMCOMPRESS NEO | C22: 410050 - FOSFATO DE CALCIO DIBAS EMCOMPRESS NEO | Lotes: 200352026 | D+8: 14/10/2026 | D22: 46307 | E22: 46305 | K22: 17 | P22: 1
A23: 410057 | B23: POLISSORBATO 80 NEO | C23: 410057 - POLISSORBATO 80 NEO | Lotes: 209562026 / 209552026 | D+8: 09/10/2026 | Particularidades: Solução repouso por 10 dias | D23: 46302 | E23: 46301 | K23: 17 | P23: 1
A24: 410070 | B24: GOMA XANTANA NEO | C24: 410070 - GOMA XANTANA NEO | Lotes: 141212026 | D+8: 09/10/2026 | D24: 46302 | E24: 46301 | K24: 9 | M24: 1 | P24: 2
A25: 410072 | B25: BASE POLIETILENO PETROLATO NEO | C25: 410072 - BASE POLIETILENO PETROLATO NEO | Lotes: 24332024 / 73922026 / 202592026 / 208552026 / 208632026 / 206342026 / 207052026 / 207062026 | D+8: 29/08/2026 | D25: 46261 | E25: 46260 | G25: 1 | J25: 7 | P25: 2
A26: 410108 | B26: AROMA MENTA LIMAO N 9068 13 GIVAUDAN NEO | C26: 410108 - AROMA MENTA LIMAO N 9068 13 GIVAUDAN NEO | Lotes: 194942026 | D+8: 14/10/2026 | D26: 46307 | E26: 46305 | G26: 1 | J26: 3 | P26: 2
A27: 410120 | B27: EUDRAGIT L30 D55 NEO | C27: 410120 - EUDRAGIT L30 D55 NEO | Lotes: 176862026 | D+8: 13/10/2026 | D27: 46305 | E27: 46305 | G27: 1 | J27: 9 | N27: 1 | P27: 3
A28: 410128 | B28: FOSFATO DE SODIO DIBASICO ANIDRO NEO | C28: 410128 - FOSFATO DE SODIO DIBASICO ANIDRO NEO | Lotes: 193342026 | D+8: 13/10/2026 | D28: 46305 | E28: 46305 | K28: 11 | P28: 1
A29: 410136 | B29: HIDROXIPROPILMETILCELULOSE 15CPS MET NEO | C29: 410136 - HIDROXIPROPILMETILCELULOSE 15CPS MET NEO | Lotes: 204122026 | D+8: 09/10/2026 | D29: 46302 | E29: 46301 | K29: 11 | M29: 1 | P29: 2
A30: 410235 | B30: OXIDO DE ZINCO GEN NEO | C30: 410235 - OXIDO DE ZINCO GEN NEO | Lotes: 204462026 | D+8: 09/10/2026 | D30: 46302 | E30: 46301 | F30: 1 | I30: 1 | L30: 10 | P30: 3
A31: 410308 | B31: GLIBENCLAMIDA NEO | C31: 410308 - GLIBENCLAMIDA NEO | Lotes: 188132026 / 188122026 | D+8: 09/10/2026 | D31: 46302 | E31: 46301 | G31: 1 | H31: 1 | L31: 8 | M31: 1 | P31: 4
A32: 410422 | B32: SACHAROMYCES BOULARDII NEO | C32: 410422 - SACHAROMYCES BOULARDII NEO | Lotes: 2172026 | D+8: 23/09/2026 | Particularidades: Refrig.: (A1) 2 ° a 8° C | D32: 46286 | E32: 46284 | L32: 11 | P32: 1
A33: 410433 | B33: CLORIDRATO DE TRAMADOL A2 NEO | C33: 410433 - CLORIDRATO DE TRAMADOL A2 NEO | Lotes: 211302026 | D+8: 10/10/2026 | Particularidades: Portaria 344 | D33: 46303 | E33: 46302 | F33: 1 | G33: 1 | L33: 12 | M33: 1 | N33: 1 | P33: 5
A34: 410452 | B34: NISTATINA GEN NEO | C34: 410452 - NISTATINA GEN NEO | Lotes: 208932026 / 208942026 / 208952026 / 208972026 / 208982026 / 208992026 / 208962026 | D+8: 07/10/2026 | D34: 46300 | E34: 46298 | F34: 1 | L34: 7 | M34: 1 | N34: 1 | P34: 4
A35: 410457 | B35: AMOXICILINA TRIHIDRATADA GEN NEO | C35: 410457 - AMOXICILINA TRIHIDRATADA GEN NEO | Lotes: 208822026 | D+8: 08/10/2026 | D35: 46301 | E35: 46300 | G35: 1 | L35: 5 | M35: 2 | N35: 4 | P35: 4
A36: 410485 | B36: MALEATO DE ENALAPRIL GEN NEO | C36: 410485 - MALEATO DE ENALAPRIL GEN NEO | Lotes: 156792026 | D+8: 19/08/2026 | D36: 46251 | E36: 46249 | G36: 1 | L36: 10 | M36: 1 | N36: 2 | P36: 4
A37: 410507 | B37: IBUPROFENO DC85 NEO | C37: 410507 - IBUPROFENO DC85 NEO | Lotes: 41432025 / 41422025 / 41412025 / 41382025 / 41402025 | D+8: 07/10/2026 | D37: 46300 | E37: 46298 | G37: 1 | L37: 5 | N37: 2 | P37: 4
A38: 410547 | B38: PARACETAMOL DC90 CPF NEO | C38: 410547 - PARACETAMOL DC90 CPF NEO | Lotes: 119902026 / 119892026 | D+8: 03/10/2026 | Particularidades: Polícia Federal | D38: 46296 | E38: 46295 | F38: 2 | G38: 1 | H38: 1 | L38: 8 | N38: 2 | P38: 5
A39: 414046 | B39: DL ACETILMETIONINA | C39: 414046 - DL ACETILMETIONINA | Lotes: 197132026 | D+8: 06/10/2026 | Particularidades: Amônio - EM TERCEIRO | D39: 46298 | E39: 46298 | F39: 1 | G39: 1 | L39: 8 | N39: 1 | P39: 4
A40: 417654 | B40: EXTR SECO PASSIFLORA INCARNATA 4-6% FLAV | C40: 417654 - EXTR SECO PASSIFLORA INCARNATA 4-6% FLAV | Lotes: 176582026 | D+8: 25/09/2026 | Particularidades: Pesticidas/ Aflatoxinas - EM TERCEIRO | D40: 46288 | E40: 46287 | F40: 2 | I40: 2 | L40: 7 | M40: 2 | P40: 4
A41: 422234 | B41: AROMA ARTIFICIAL DE AMEIXA | C41: 422234 - AROMA ARTIFICIAL DE AMEIXA | Lotes: 211022026 | D+8: 14/10/2026 | Particularidades: Inflamável | D41: 46307 | E41: 46305 | G41: 1 | J41: 3 | P41: 2
...

Sheet PAINEL - CG
B1: LEGENDA: | C1: Finalizado | D1: Investigação
B2: Iniciar Análise | C2: Em andamento | D2: Prog. em andamento
B4: FAMÍLIA | C4: PREPARO | D4: TURNO | E4: 11/05 | F4: 12/05 | G4: 13/05 | H4: 14/05 | I4: 15/05 | J4: 16/05 | K4: 17/05/2026 | L4: 18/05/2026 | M4: 19/05/2026 | N4: 20/05/2026 | O4: 21/05/2026 | P4: 22/05/2026 | Q4: 23/05/2026 | R4: 24/05/2026 | S4: 25/05/2026 | T4: 26/05/2026 | U4: 27/05/2026 | V4: 28/05/2026 | W4: 29/05/2026 | X4: 30/05/2026 | Y4: 31/05/2026 | Z4: 01/06/2026 | AA4: 02/06/2026 | AB4: 03/06/2026 | AC4: 04/06/2026 | AD4: 05/06/2026 | AE4: 06/06/2026 | AF4: 07/06/2026 | AG4: 08/06/2026 | AH4: 09/06/2026 | AI4: 10/06/2026 | AJ4: 11/06/2026 | AK4: 12/06/2026 | AL4: 13/06/2026 | AM4: 14/06/2026 | AN4: 15/06/2026 | AO4: 16/06/2026 | AP4: 17/06/2026 | AQ4: 18/06/2026 | AR4: 19/06/2026 | AS4: 20/06/2026 | AT4: 21/06/2026 | AU4: 22/06/2026 | AV4: 23/06/2026 | AW4: 24/06/2026 | AX4: 25/06/2026 | AY4: 26/06/2026 | AZ4: 27/06/2026 | BA4: 28/06/2026 | BB4: 29/06/2026 | BC4: 30/06/2026 | BD4: 01/07/2026 | BE4: 02/07/2026 | BF4: 03/07/2026 | BG4: 04/07/2026 | BH4: 05/07/2026 | BI4: 06/07/2026 | BJ4: 07/07/2026 | BK4: 08/07/2026 | BL4: 09/07/2026 | BM4: 10/07/2026 | BN4: 11/07/2026 | BO4: 12/07/2026 | BP4: 13/07/2026 | BQ4: 14/07/2026 | BR4: 15/07/2026 | BS4: 16/07/2026 | BT4: 17/07/2026 | BU4: 18/07/2026 | BV4: 19/07/2026 | BW4: 20/07/2026 | BX4: 21/07/2026 | BY4: 22/07/2026 | BZ4: 23/07/2026 | CA4: 24/07/2026 | CB4: 25/07/2026 | CC4: 26/07/2026 | CD4: 27/07/2026 | CE4: 28/07/2026 | CF4: 29/07/2026 | CG4: 30/07/2026 | CH4: 31/07/2026 | CI4: 01/08/2026 | CJ4: 02/08/2026 | CK4: 03/08/2026 | CL4: 04/08/2026 | CM4: 05/08/2026 | CN4: 06/08/2026 | CO4: 07/08/2026 | CP4: 08/08/2026 | CQ4: 09/08/2026 | CR4: 10/08/2026 | CS4: 11/08/2026 | CT4: 12/08/2026 | CU4: 13/08/2026 | CV4: 14/08/2026 | CW4: 15/08/2026 | CX4: 16/08/2026 | CY4: 17/08/2026 | CZ4: 18/08/2026 | DA4: 19/08/2026 | DB4: 20/08/2026 | DC4: 21/08/2026 | DD4: 22/08/2026 | DE4: 23/08/2026 | DF4: 24/08/2026 | DG4: 25/08/2026 | DH4: 26/08/2026 | DI4: 27/08/2026 | DJ4: 28/08/2026 | DK4: 29/08/2026 | DL4: 30/08/2026 | DM4: 31/08/2026 | DN4: 01/09/2026 | DO4: 02/09/2026 | DP4: 03/09/2026 | DQ4: 04/09/2026 | DR4: 05/09/2026 | DS4: 06/09/2026 | DT4: 07/09/2026 | DU4: 08/09/2026 | DV4: 09/09/2026 | DW4: 10/09/2026 | DX4: 11/09/2026 | DY4: 12/09/2026 | DZ4: 13/09/2026 | EA4: 14/09/2026 | EB4: 15/09/2026 | EC4: 16/09/2026 | ED4: 17/09/2026 | EE4: 18/09/2026 | EF4: 19/09/2026 | EG4: 20/09/2026 | EH4: 21/09/2026 | EI4: 22/09/2026 | EJ4: 23/09/2026 | EK4: 24/09/2026 | EL4: 25/09/2026 | EM4: 26/09/2026 | EN4: 27/09/2026 | EO4: 28/09/2026 | EP4: 29/09/2026 | EQ4: 30/09/2026 | ER4: 01/10/2026 | ES4: 02/10/2026 | ET4: 03/10/2026 | EU4: 04/10/2026 | EV4: 05/10/2026 | EW4: 06/10/2026 | EX4: 07/10/2026 | EY4: 08/10/2026 | EZ4: 09/10/2026 | FA4: 10/10/2026 | FB4: 11/10/2026 | FC4: 12/10/2026 | FD4: 13/10/2026 | FE4: 14/10/2026 | FF4: 15/10/2026 | FG4: 16/10/2026 | FH4: 17/10/2026 | FI4: 18/10/2026 | FJ4: 19/10/2026 | FK4: 20/10/2026 | FL4: 21/10/2026 | FM4: 22/10/2026 | FN4: 23/10/2026 | FO4: 24/10/2026 | FP4: 25/10/2026 | FQ4: 26/10/2026 | FR4: 27/10/2026 | FS4: 28/10/2026 | FT4: 29/10/2026 | FU4: 30/10/2026 | FV4: 31/10/2026 | FW4: 01/11/2026 | FX4: 02/11/2026 | FY4: 03/11/2026 | FZ4: 04/11/2026 | GA4: 05/11/2026 | GB4: 06/11/2026 | GC4: 07/11/2026 | GD4: 08/11/2026 | GE4: 09/11/2026 | GF4: 10/11/2026 | GG4: 11/11/2026 | GH4: 12/11/2026 | GI4: 13/11/2026 | GJ4: 14/11/2026 | GK4: 15/11/2026 | GL4: 16/11/2026 | GM4: 17/11/2026 | GN4: 18/11/2026 | GO4: 19/11/2026 | GP4: 20/11/2026 | GQ4: 21/11/2026 | GR4: 22/11/2026 | GS4: 23/11/2026 | GT4: 24/11/2026 | GU4: 25/11/2026 | GV4: 26/11/2026 | GW4: 27/11/2026 | GX4: 28/11/2026 | GY4: 29/11/2026 | GZ4: 30/11/2026 | HA4: 01/12/2026 | HB4: 02/12/2026 | HC4: 03/12/2026 | HD4: 04/12/2026 | HE4: 05/12/2026 | HF4: 06/12/2026 | HG4: 07/12/2026 | HH4: 08/12/2026 | HI4: 09/12/2026 | HJ4: 10/12/2026 | HK4: 11/12/2026 | HL4: 12/12/2026 | HM4: 13/12/2026 | HN4: 14/12/2026 | HO4: 15/12/2026 | HP4: 16/12/2026 | HQ4: 17/12/2026 | HR4: 18/12/2026 | HS4: 19/12/2026 | HT4: 20/12/2026 | HU4: 21/12/2026 | HV4: 22/12/2026 | HW4: 23/12/2026 | HX4: 24/12/2026 | HY4: 25/12/2026 | HZ4: 26/12/2026 | IA4: 27/12/2026 | IB4: 28/12/2026 | IC4: 29/12/2026 | ID4: 30/12/2026 | IE4: 31/12/2026 | IF4: 01/01/2027 | IG4: 02/01/2027 | IH4: 03/01/2027
